Workbook

Sheet Register
A1: ID | B1: Audit | C1: Finding | D1: Severity | E1: Fix class | F1: Status | G1: Verification | H1: Verification note / evidence
A2: SEC-C1 | B2: Security | C2: Live production credentials and employee PII committed to the repo, in the one path CI is told not to scan | D2: Critical | E2: Process + purge | F2: Fixed | G2: Verified in code | H2: Scanner un-excluded AND pattern set widened; 7 credential files cleaned (5 more than the audit cited, incl. 2 Groq keys CI found). CREDENTIALS ROTATED BY OWNER 2026-08-04. History still contains them — purge declined, rotation makes it harmless.
A3: SEC-C2 | B3: Security | C3: Logout does not end the session; the refresh token stays valid | D3: Critical | E3: Code, quick | F3: Fixed | G3: Verified in code | H3: Access tokens now carry `sid`; logout revokes the session from the TOKEN, not a body field the client never sent. Both issuance paths (login + refresh rotation) carry it — a test asserts every signAccessToken call site does. Response reports session_revoked honestly. Verified to FAIL 4/6 against the old service. Commit 809caad.
A4: SEC-C3 | B4: Security | C4: No brute-force protection on any authentication endpoint; failed-login counter never enforced | D4: Critical | E4: Code, quick | F4: Fixed | G4: Verified in code | H4: Limiters on all 11 credential surfaces across 3 tiers, AND the failed-login counter is now enforced as a decaying cooldown (migration 0495). 7 assertions on the curve.
A5: SEC-H1 | B5: Security | C5: The AI assistant executes business writes with no permission check at all | D5: High | E5: Code | F5: Open | G5: As reported
A6: SEC-H2 | B6: Security | C6: Platform Console credential-store routes have no capability gate | D6: High | E6: Code, quick | F6: Fixed | G6: Verified in code | H6: requireCap on all 8 routes; settings.read/write + migration 0032; structural test asserts all 47 platform routes are gated.
A7: SEC-H3 | B7: Security | C7: Request-body keys become SQL column identifiers on modules using the passthrough validator | D7: High | E7: Code | F7: Open | G7: As reported
A8: SEC-H4 | B8: Security | C8: MOD-67 'edit' can take over any account, including the CEO, with no re-authentication | D8: High | E8: Code | F8: Open | G8: As reported
A9: SEC-H5 | B9: Security | C9: Rate limiting is bypassable: trust proxy true with an IP-keyed in-memory store | D9: High | E9: Config + code | F9: Fixed | G9: Verified in code | H9: Redis-backed limiter store; trust proxy is now a hop count (TRUST_PROXY_HOPS), not `true`.
A10: SEC-H6 | B10: Security | C10: Portal and platform accounts protected by an 8-char password, no complexity or breach check | D10: High | E10: Code, quick | F10: Open | G10: As reported
A11: SEC-M1 | B11: Security | C11: Access tokens are not session-bound: revocation does not revoke | D11: Medium | E11: Code | F11: Open | G11: As reported
A12: SEC-M2 | B12: Security | C12: killSession has no ownership predicate | D12: Medium | E12: Code, quick | F12: Fixed | G12: Verified in code | H12: killSession is now always scoped to the acting user. Folded into the SEC-C2 fix. Commit 809caad.
A13: SEC-M3 | B13: Security | C13: Document vault authorization is module-level, not record-level | D13: Medium | E13: Code | F13: Open | G13: As reported
A14: SEC-M4 | B14: Security | C14: The Socket.IO handshake lets the client name its own tenant | D14: Medium | E14: Code | F14: Open | G14: As reported
A15: SEC-M5 | B15: Security | C15: One JWT secret across all three auth tiers, and no tenant claim in any token | D15: Medium | E15: Structural | F15: Open | G15: As reported
A16: SEC-M6 | B16: Security | C16: Platform tier has no session store, no revocation and no 2FA | D16: Medium | E16: Structural | F16: Open | G16: As reported
A17: SEC-M7 | B17: Security | C17: One database credential and one encryption key shared across all tenants | D17: Medium | E17: Structural | F17: Open | G17: As reported
A18: SEC-M8 | B18: Security | C18: CSP permits unsafe-inline scripts application-wide | D18: Medium | E18: Config | F18: Open | G18: Verified in code | H18: server.js: script-src ['self','unsafe-inline'], script-src-attr ['unsafe-inline']
A19: SEC-M9 | B19: Security | C19: Dependency vulnerabilities present, gate non-blocking, no SAST or Dependabot | D19: Medium | E19: CI | F19: Open | G19: Verified in code | H19: ci.yaml:79 continue-on-error: true on npm audit
A20: SEC-L1 | B20: Security | C20: Containers run as root; compose bind-mounts the document vault into them | D20: Low | E20: Config, quick | F20: Open | G20: As reported
A21: SEC-L2 | B21: Security | C21: Redis unauthenticated and keyspace not tenant-namespaced; invalidateGrants uses blocking KEYS | D21: Low | E21: Config + code | F21: Open | G21: As reported
A22: SEC-L3 | B22: Security | C22: Refresh token in web storage | D22: Low | E22: Code (blocked by M8, C2) | F22: Open | G22: As reported
A23: SEC-L4 | B23: Security | C23: Logger redaction misses refresh_token, access_token, password_hash, totp_secret_enc, secret_enc | D23: Low | E23: Config, quick | F23: Fixed | G23: Verified in code | H23: REDACT_PATHS widened; both top-level and nested forms generated from SENSITIVE_KEYS.
A24: SEC-L5 | B24: Security | C24: The anonymous-surface test is shallow - matches authMiddleware anywhere in the router | D24: Low | E24: Test, quick | F24: Open | G24: As reported
A25: SEC-L6 | B25: Security | C25: src/middleware/audit.js is dead code, never imported or mounted | D25: Low | E25: Delete | F25: Open | G25: As reported
A26: DI-5.5 | B26: Data Integrity | C26: Asset depreciation never posts to the GL and records itself as posted | D26: Critical | E26: Code, quick | F26: Fixed | G26: Verified in code | H26: Depreciation now reaches the GL: account_code + sourceDocRef, and a ledger rejection FAILS the call instead of setting posted=true with entry_id NULL. 11 assertions, verified to FAIL against the pre-fix file. Sweep found only asset+payroll; a grep-as-a-test blocks a third. Commit 62a9646. NOTE: existing bad rows need scripts/db/reconcile-depreciation.js.
A27: DI-5.1 | B27: Data Integrity | C27: Inventory balance: no transaction, no lock, no DB floor | D27: Critical | E27: Code + constraint | F27: Open | G27: As reported
A28: DI-5.2 | B28: Data Integrity | C28: Shared CRUD kit writes business row, event and audit as three separate commits | D28: Critical | E28: Code, mechanical | F28: Open | G28: As reported
A29: DI-1.1 | B29: Data Integrity | C29: ~100 money/quantity columns with no CHECK constraint | D29: Critical | E29: Migration + data probe | F29: Open | G29: As reported
A30: DI-1.2 | B30: Data Integrity | C30: No cross-row sum invariants (over-allocation, over-justification) | D30: Critical | E30: Migration + data probe | F30: Open | G30: As reported
A31: DI-2.1 | B31: Data Integrity | C31: ON DELETE CASCADE on financial and inventory history | D31: Critical | E31: Migration, careful | F31: Open | G31: As reported
A32: DI-1.3 | B32: Data Integrity | C32: Multi-currency ledger lines are stored but never reconciled to a base currency | D32: High | E32: Migration + code | F32: Open | G32: As reported
A33: DI-1.6 | B33: Data Integrity | C33: doc_number is not unique anywhere | D33: High | E33: Migration + dedupe | F33: Open | G33: As reported
A34: DI-1.8 | B34: Data Integrity | C34: tax_code effective windows can overlap, producing wrong VAT silently | D34: High | E34: Migration + code | F34: Open | G34: As reported
A35: DI-1.9 | B35: Data Integrity | C35: cached_receivables read but never written; credit limit inert | D35: High | E35: Code, quick | F35: Open | G35: As reported
A36: DI-2.2 | B36: Data Integrity | C36: 295 of 351 foreign keys have no index on the referencing column | D36: High | E36: Migration, online | F36: Open | G36: As reported
A37: DI-2.4 | B37: Data Integrity | C37: Sandbox actor-FK guard applied inconsistently | D37: High | E37: Code + design | F37: Open | G37: As reported
A38: DI-3.1 | B38: Data Integrity | C38: Migration application is not atomic with its ledger entry | D38: High | E38: Tooling | F38: Open | G38: As reported
... A40: DI-3.3 | B40: Data Integrity | C40: Migration files and the live schema have already drifted (notification_preference) | D40: High | E40: Verify + tooling | F40: Open | G40: As reported
A41: DI-3.5 | B41: Data Integrity | C41: No migration is reversible; no down concept exists in the tooling | D41: High | E41: Policy | F41: Partially fixed | G41: As reported | H41: New migrations must declare -- DOWN or -- IRREVERSIBLE (CI gate). The 92 pre-existing migrations are still irreversible and deliberately not retro-fitted.
...

Sheet Summary
A1: Praxis LS - consolidated audit register, 2026-08-04
A2: Seven Phase-0 audits. One row per headline finding on the Register sheet.
A4: Audit | B4: Critical | C4: High | D4: Medium-High | E4: Medium | F4: Low-Medium | G4: Low | H4: Total
A5: Security | B5: =COUNTIFS(Register!$B$2:$B$206,$A5,Register!$D$2:$D$206,B$4) -> 3 | C5: =COUNTIFS(Register!$B$2:$B$206,$A5,Register!$D$2:$D$206,C$4) -> 6 | D5: =COUNTIFS(Register!$B$2:$B$206,$A5,Register!$D$2:$D$206,D$4) -> 0 | E5: =COUNTIFS(Register!$B$2:$B$206,$A5,Register!$D$2:$D$206,E$4) -> 9 | F5: =COUNTIFS(Register!$B$2:$B$206,$A5,Register!$D$2:$D$206,F$4) -> 0 | G5: =COUNTIFS(Register!$B$2:$B$206,$A5,Register!$D$2:$D$206,G$4) -> 6 | H5: =SUM(B5:G5) -> 24
A6: Data Integrity | B6: =COUNTIFS(Register!$B$2:$B$206,$A6,Register!$D$2:$D$206,B$4) -> 6 | C6: =COUNTIFS(Register!$B$2:$B$206,$A6,Register!$D$2:$D$206,C$4) -> 16 | D6: =COUNTIFS(Register!$B$2:$B$206,$A6,Register!$D$2:$D$206,D$4) -> 0 | E6: =COUNTIFS(Register!$B$2:$B$206,$A6,Register!$D$2:$D$206,E$4) -> 10 | F6: =COUNTIFS(Register!$B$2:$B$206,$A6,Register!$D$2:$D$206,F$4) -> 0 | G6: =COUNTIFS(Register!$B$2:$B$206,$A6,Register!$D$2:$D$206,G$4) -> 1 | H6: =SUM(B6:G6) -> 33
A7: Observability | B7: =COUNTIFS(Register!$B$2:$B$206,$A7,Register!$D$2:$D$206,B$4) -> 13 | C7: =COUNTIFS(Register!$B$2:$B$206,$A7,Register!$D$2:$D$206,C$4) -> 12 | D7: =COUNTIFS(Register!$B$2:$B$206,$A7,Register!$D$2:$D$206,D$4) -> 0 | E7: =COUNTIFS(Register!$B$2:$B$206,$A7,Register!$D$2:$D$206,E$4) -> 6 | F7: =COUNTIFS(Register!$B$2:$B$206,$A7,Register!$D$2:$D$206,F$4) -> 0 | G7: =COUNTIFS(Register!$B$2:$B$206,$A7,Register!$D$2:$D$206,G$4) -> 0 | H7: =SUM(B7:G7) -> 31
A8: API Contract | B8: =COUNTIFS(Register!$B$2:$B$206,$A8,Register!$D$2:$D$206,B$4) -> 5 | C8: =COUNTIFS(Register!$B$2:$B$206,$A8,Register!$D$2:$D$206,C$4) -> 8 | D8: =COUNTIFS(Register!$B$2:$B$206,$A8,Register!$D$2:$D$206,D$4) -> 0 | E8: =COUNTIFS(Register!$B$2:$B$206,$A8,Register!$D$2:$D$206,E$4) -> 13 | F8: =COUNTIFS(Register!$B$2:$B$206,$A8,Register!$D$2:$D$206,F$4) -> 0 | G8: =COUNTIFS(Register!$B$2:$B$206,$A8,Register!$D$2:$D$206,G$4) -> 4 | H8: =SUM(B8:G8) -> 30
A9: Perf & Architecture | B9: =COUNTIFS(Register!$B$2:$B$206,$A9,Register!$D$2:$D$206,B$4) -> 3 | C9: =COUNTIFS(Register!$B$2:$B$206,$A9,Register!$D$2:$D$206,C$4) -> 9 | D9: =COUNTIFS(Register!$B$2:$B$206,$A9,Register!$D$2:$D$206,D$4) -> 0 | E9: =COUNTIFS(Register!$B$2:$B$206,$A9,Register!$D$2:$D$206,E$4) -> 6 | F9: =COUNTIFS(Register!$B$2:$B$206,$A9,Register!$D$2:$D$206,F$4) -> 0 | G9: =COUNTIFS(Register!$B$2:$B$206,$A9,Register!$D$2:$D$206,G$4) -> 2 | H9: =SUM(B9:G9) -> 20
A10: Test & CI/CD | B10: =COUNTIFS(Register!$B$2:$B$206,$A10,Register!$D$2:$D$206,B$4) -> 7 | C10: =COUNTIFS(Register!$B$2:$B$206,$A10,Register!$D$2:$D$206,C$4) -> 19 | D10: =COUNTIFS(Register!$B$2:$B$206,$A10,Register!$D$2:$D$206,D$4) -> 2 | E10: =COUNTIFS(Register!$B$2:$B$206,$A10,Register!$D$2:$D$206,E$4) -> 12 | F10: =COUNTIFS(Register!$B$2:$B$206,$A10,Register!$D$2:$D$206,F$4) -> 3 | G10: =COUNTIFS(Register!$B$2:$B$206,$A10,Register!$D$2:$D$206,G$4) -> 4 | H10: =SUM(B10:G10) -> 47
A11: Desktop UI | B11: =COUNTIFS(Register!$B$2:$B$206,$A11,Register!$D$2:$D$206,B$4) -> 5 | C11: =COUNTIFS(Register!$B$2:$B$206,$A11,Register!$D$2:$D$206,C$4) -> 7 | D11: =COUNTIFS(Register!$B$2:$B$206,$A11,Register!$D$2:$D$206,D$4) -> 0 | E11: =COUNTIFS(Register!$B$2:$B$206,$A11,Register!$D$2:$D$206,E$4) -> 8 | F11: =COUNTIFS(Register!$B$2:$B$206,$A11,Register!$D$2:$D$206,F$4) -> 0 | G11: =COUNTIFS(Register!$B$2:$B$206,$A11,Register!$D$2:$D$206,G$4) -> 0 | H11: =SUM(B11:G11) -> 20
A12: Total | B12: =SUM(B5:B11) -> 42 | C12: =SUM(C5:C11) -> 77 | D12: =SUM(D5:D11) -> 2 | E12: =SUM(E5:E11) -> 64 | F12: =SUM(F5:F11) -> 3 | G12: =SUM(G5:G11) -> 17 | H12: =SUM(H5:H11) -> 205
A14: Status roll-up
A15: Open | B15: =COUNTIF(Register!$F$2:$F$206,$A15) -> 164
A16: Partially fixed | B16: =COUNTIF(Register!$F$2:$F$206,$A16) -> 5
A17: Fixed | B17: =COUNTIF(Register!$F$2:$F$206,"Fixed") -> 31
A18: Largely fixed (superseded) | B18: =COUNTIF(Register!$F$2:$F$206,$A18) -> 0
A19: Closed | B19: =COUNTIF(Register!$F$2:$F$206,$A19) -> 3
A20: Independently verified in code | B20: =COUNTIF(Register!$G$2:$G$206,"Verified in code") -> 40
